Workbook

Sheet Daftar Akun Spender by web
A1: No | B1: Nama Akun | C1: Username | D1: Hadiah | E1: Tier | F1: Koin Total | G1: Label Utama | H1: Label Lain / Keterangan | I1: Catatan | J1: Sudah Chat? | K1: Sudah Dibalas?
A2: 1 | B2: RFX | C2: @rfx4981 | D2: 3430 | E2: 3 | F2: 1211566 | G2: Whale | H2: Aktif di banyak room (+4) | I2: Peringkat teratas | J2: Sudah | K2: Belum
A3: 2 | B3: Noel Clyne | C3: @noel.clyne | D3: 1006 | E3: 4 | F3: 1039106 | G3: Whale | H3: Aktif di banyak room (+4) | J3: Sudah | K3: Belum
A4: 3 | B4: It's me Zayn | C4: @batangenyongaccountant | D4: 419 | E4: 6 | F4: 607404 | G4: Whale | H4: Aktif di banyak room (+5) | J4: Sudah | K4: Belum
A5: 4 | B5: -_- | C5: @dontfindme7127 | D5: 1970 | E5: 3 | F5: 596978 | G5: Whale | H5: Aktif di banyak room (+5) | J5: Sudah | K5: Belum
A6: 5 | B6: HelmsDeep | C6: @helmsdeep5 | D6: 2785 | E6: 6 | F6: 572837 | G6: Whale | H6: Aktif di banyak room (+3) | J6: Sudah | K6: Belum
A7: 6 | B7: Devil.Prada | C7: @devilredh | D7: 757 | E7: 4 | F7: 544210 | G7: Whale | H7: Aktif di banyak room (+5) | J7: Sudah | K7: Belum
A8: 7 | B8: MrSin | C8: @mrsin30 | D8: 13239 | E8: 3 | F8: 501213 | G8: Whale | H8: Aktif di banyak room (+4) | J8: Sudah | K8: Belum
A9: 8 | B9: SKY | C9: @skycloud118 | D9: 1419 | E9: 6 | F9: 362514 | G9: Whale | H9: Loyal room supporter (+3) | J9: Sudah | K9: Belum
A10: 9 | B10: jooooo | C10: @pjsc070304 | D10: 136 | E10: 6 | F10: 329979 | G10: Whale | H10: Rata-rata 5 gift per hari (+2) | J10: Sudah | K10: Belum
A11: 10 | B11: Alexander | C11: @a1_exander | D11: 2317 | E11: 6 | F11: 290317 | G11: Whale | H11: Rata-rata 22 gift per hari (+3) | J11: Sudah | K11: Belum
A12: 11 | B12: Zull | C12: @zull25563 | D12: 461 | E12: 6 | F12: 283968 | G12: Whale | H12: Aktif di banyak room (+6) | J12: Belum | K12: Belum
A13: 12 | B13: 狮子 (◝ᴗ◜) | C13: @ecova2026 | D13: 8164 | E13: 6 | F13: 267810 | G13: Whale | H13: Aktif di banyak room (+6) | J13: Belum | K13: Belum
A14: 13 | B14: Mr.Arman | C14: @mr.arman336 | D14: 22 | E14: 6 | F14: 248797 | G14: Whale | H14: Sudden gift terakhir: 15.000 coin (+2) | J14: Belum | K14: Belum
... A25: 24 | B25: liyann | C25: @liiyann04 | D25: 411 | E25: 2 | F25: 138790 | G25: Whale | H25: Aktif di banyak room (+5) | J25: Belum | K25: Belum
A26: 25 | B26: virus | C26: @excelcaw | D26: 209 | E26: 3 | F26: 137013 | G26: Whale | H26: Loyal room supporter (+4) | I26: Peringkat 1 halaman 1 | J26: Belum | K26: Belum
A27: 26 | B27: •KETUA• 林Sen | C27: @kapan.aku.benar | D27: 4080 | E27: 4 | F27: 131246 | G27: Whale | H27: Aktif di banyak room (+5) | J27: Belum | K27: Belum
A28: 27 | B28: ⅄X | C28: @yxlolll | D28: 1697 | E28: 6 | F28: 128085 | G28: Whale | H28: Loyal room supporter (+4) | J28: Belum | K28: Belum
A29: 28 | B29: (nama kosong) | C29: @bossman23000 | D29: 7757 | E29: 6 | F29: 124974 | G29: Whale | H29: Aktif di banyak room (+4) | J29: Belum | K29: Belum
A30: 29 | B30: JM'77 | C30: @bukitberbunga77 | D30: 2041 | E30: 4 | F30: 124239 | G30: Whale | H30: Aktif di banyak room (+5) | J30: Belum | K30: Belum
A31: 30 | B31: nitrocrew00 | C31: @nitrocrew00 | D31: 317 | E31: 6 | F31: 123926 | G31: Whale | H31: Loyal room supporter (+2) | J31: Belum | K31: Belum
A32: 31 | B32: yuki | C32: @user73087249 | D32: 163 | E32: 6 | F32: 123920 | G32: Whale | H32: Loyal room supporter (+2) | J32: Belum | K32: Belum
A33: 32 | B33: Erlang Tan | C33: @dakartto | D33: 98 | E33: 6 | F33: 123416 | G33: Whale | H33: Loyal room supporter (+4) | J33: Belum | K33: Belum
A34: 33 | B34: Teteh Cengeng | C34: @momymonster24 | D34: 582 | E34: 3 | F34: 118787 | G34: Whale | H34: Rata-rata 35 gift per hari (+3) | J34: Belum | K34: Belum
A35: 34 | B35: PapaLoneWolf(VE… | C35: @lonewol695 | D35: 263 | E35: 6 | F35: 117042 | G35: Whale | H35: Rata-rata 29 gift per hari (+3) | J35: Belum | K35: Belum
A36: 35 | B36: ♏"ŔɛMĪZŦA=›ß♡ŔD… | C36: @joe_remizta | D36: 4010 | E36: 3 | F36: 115430 | G36: Whale | H36: Aktif di banyak room (+5) | J36: Belum | K36: Belum
A37: 36 | B37: Pirouette21 | C37: @juste_v5 | D37: 3243 | E37: 4 | F37: 114480 | G37: Whale | H37: Aktif di banyak room (+5) | J37: Belum | K37: Belum
A38: 37 | B38: WAX | C38: @wax67753 | D38: 10106 | E38: 3 | F38: 112987 | G38: Whale | H38: Aktif di banyak room (+5) | J38: Belum | K38: Belum
... A67: 66 | B67: ことら | C67: @kuzirasann777 | D67: 12078 | E67: 6 | F67: 70712 | G67: Whale | H67: Sering kirim gift kecil (+5) | J67: Belum | K67: Belum
A68: 67 | B68: mutanunivers | C68: @mutanunivers | D68: 5396 | E68: 5 | F68: 70089 | G68: Whale | H68: Aktif di banyak room (+5) | I68: Halaman 3/87 (peringkat 51-75) | J68: Belum | K68: Belum
A69: 68 | B69: Youngsons | C69: @youngsons | D69: 4926 | E69: 4 | F69: 68754 | G69: Whale | H69: Aktif di banyak room (+5) | I69: Halaman 3/87 | J69: Belum | K69: Belum
A70: 69 | B70: Americano. | C70: @hawe260604 | D70: 2626 | E70: 5 | F70: 68473 | G70: Whale | H70: Rata-rata 54 gift per hari (+3) | I70: Halaman 3/87 | J70: Belum | K70: Belum
A71: 70 | B71: Figment of your Rage Bait… | C71: @figmentofyourragebaiter | D71: 13 | E71: 6 | F71: 67299 | G71: Whale | H71: Loyal room supporter (+3) | I71: Halaman 3/87 | J71: Belum | K71: Belum
A72: 71 | B72: littelpizza | C72: @littelpizza | D72: 35 | E72: 4 | F72: 66367 | G72: Whale | H72: Aktif di banyak room (+4) | I72: Halaman 3/87 | J72: Belum | K72: Belum
A73: 72 | B73: For you | C73: @for.you.233 | D73: 1525 | E73: 6 | F73: 65314 | G73: Whale | H73: Rata-rata 23 gift per hari (+3) | I73: Halaman 3/87 | J73: Belum | K73: Belum
A74: 73 | B74: Allen | C74: @all.en4u | D74: 23 | E74: 6 | F74: 64556 | G74: Whale | H74: Loyal room supporter (+4) | J74: Belum | K74: Belum
A75: 74 | B75: Koko ku | C75: @koko.ku7 | D75: 547 | E75: 5 | F75: 64384 | G75: Whale | H75: Aktif di banyak room (+5) | I75: Muncul di 2 screenshot; nilai lain: 39.178 koin (gbr 25) | J75: Belum | K75: Belum
A76: 75 | B76: Apanyak | C76: @the_night_skies | D76: 1153 | E76: 6 | F76: 64383 | G76: Whale | H76: Aktif di banyak room (+5) | J76: Belum | K76: Belum
A77: 76 | B77: Alice | C77: @aliceee_1224 | D77: 261 | E77: 6 | F77: 64374 | G77: Whale | H77: Loyal room supporter (+5) | J77: Belum | K77: Belum
A78: 77 | B78: Auda | C78: @auda.del | D78: 2414 | E78: 2 | F78: 62596 | G78: Whale | H78: Aktif di banyak room (+4) | J78: Belum | K78: Belum
...

Sheet Ringkasan (acc spender by web)
A1: Ringkasan Progres
A3: Total akun | B3: =COUNTA('Daftar Akun Spender by web'!B2:B330) -> 329
A4: Sudah chat | B4: =COUNTIF('Daftar Akun Spender by web'!J2:J330,"Sudah") -> 10
A5: Belum chat | B5: =COUNTIF('Daftar Akun Spender by web'!J2:J330,"Belum") -> 319
A6: Sudah dibalas | B6: =COUNTIF('Daftar Akun Spender by web'!K2:K330,"Sudah") -> 0
A7: Tidak ada respon | B7: =COUNTIF('Daftar Akun Spender by web'!K2:K330,"Tidak ada respon") -> 0
A8: Whale | B8: =COUNTIF('Daftar Akun Spender by web'!G2:G330,"Whale") -> 107
A9: High spender | B9: =COUNTIF('Daftar Akun Spender by web'!G2:G330,"High spender") -> 175
A10: Supporter | B10: =COUNTIF('Daftar Akun Spender by web'!G2:G330,"Supporter") -> 46
A13: Catatan
A14: Data dibaca manual dari 56 screenshot leaderboard (jam 17.35-18.56); akun yang muncul lebih dari sekali digabung per username, koin tertinggi dipakai.
A15: Kolom K-L (kuning) diisi manual: pilih dari dropdown. Default 'Belum'.
A16: Sebagian nama/tier terpotong di tepi screenshot; ditandai '…' atau di kolom Catatan.
A17: Angka koin dan hadiah berbeda antar screenshot karena diambil di waktu/halaman berbeda; cek kolom Catatan.

Sheet Daftar Nama dan Status Pengumpu
A1: No | B1: Nama | C1: Centang | D1: Status | F1: Ringkasan
A2: 1 | B2: monarch77 | C2: =TRUE() -> TRUE | D2: =IF(C2,"Sudah","Belum") -> Sudah | F2: Sudah | G2: =COUNTIF(C2:C55,TRUE()) -> 28
A3: 2 | B3: kebun air | C3: =TRUE() -> TRUE | D3: =IF(C3,"Sudah","Belum") -> Sudah | F3: Belum | G3: =COUNTIF(C2:C55,FALSE()) -> 26
A4: 3 | B4: hanssel | C4: =TRUE() -> TRUE | D4: =IF(C4,"Sudah","Belum") -> Sudah | F4: Total | G4: =G2+G3 -> 54
A5: 4 | B5: kambing terbang | C5: =TRUE() -> TRUE | D5: =IF(C5,"Sudah","Belum") -> Sudah | F5: Progres | G5: =IF(G4=0,0,G2/G4) -> 0.51851852
A6: 5 | B6: dewolves | C6: =TRUE() -> TRUE | D6: =IF(C6,"Sudah","Belum") -> Sudah
A7: 6 | B7: bang aji | C7: =TRUE() -> TRUE | D7: =IF(C7,"Sudah","Belum") -> Sudah | F7: Klik kotak di kolom C untuk centang (Sudah)
A8: 7 | B8: luis | C8: =TRUE() -> TRUE | D8: =IF(C8,"Sudah","Belum") -> Sudah
A9: 8 | B9: zeroaxel | C9: =TRUE() -> TRUE | D9: =IF(C9,"Sudah","Belum") -> Sudah
A10: 9 | B10: nobody | C10: =TRUE() -> TRUE | D10: =IF(C10,"Sudah","Belum") -> Sudah
A11: 10 | B11: dibi | C11: =TRUE() -> TRUE | D11: =IF(C11,"Sudah","Belum") -> Sudah
A12: 11 | B12: gowther | C12: =TRUE() -> TRUE | D12: =IF(C12,"Sudah","Belum") -> Sudah
A13: 12 | B13: jepang | C13: =TRUE() -> TRUE | D13: =IF(C13,"Sudah","Belum") -> Sudah
A14: 13 | B14: ozan | C14: =TRUE() -> TRUE | D14: =IF(C14,"Sudah","Belum") -> Sudah
A15: 14 | B15: han | C15: =TRUE() -> TRUE | D15: =IF(C15,"Sudah","Belum") -> Sudah
A16: 15 | B16: axheno | C16: =TRUE() -> TRUE | D16: =IF(C16,"Sudah","Belum") -> Sudah
A17: 16 | B17: iblis | C17: =TRUE() -> TRUE | D17: =IF(C17,"Sudah","Belum") -> Sudah
A18: 17 | B18: kimchi | C18: =TRUE() -> TRUE | D18: =IF(C18,"Sudah","Belum") -> Sudah
A19: 18 | B19: edhy | C19: =TRUE() -> TRUE | D19: =IF(C19,"Sudah","Belum") -> Sudah
... A29: 28 | B29: krazly | C29: =TRUE() -> TRUE | D29: =IF(C29,"Sudah","Belum") -> Sudah
A30: 29 | B30: yeka | C30: =FALSE() -> FALSE | D30: =IF(C30,"Sudah","Belum") -> Belum
A31: 30 | B31: alpin | C31: =FALSE() -> FALSE | D31: =IF(C31,"Sudah","Belum") -> Belum
A32: 31 | B32: NOVA_MILITARY | C32: =FALSE() -> FALSE | D32: =IF(C32,"Sudah","Belum") -> Belum
A33: 32 | B33: Bob's 4lyfe | C33: =FALSE() -> FALSE | D33: =IF(C33,"Sudah","Belum") -> Belum
A34: 33 | B34: luislunatico1989 | C34: =FALSE() -> FALSE | D34: =IF(C34,"Sudah","Belum") -> Belum
A35: 34 | B35: rapin | C35: =FALSE() -> FALSE | D35: =IF(C35,"Sudah","Belum") -> Belum
A36: 35 | B36: love | C36: =FALSE() -> FALSE | D36: =IF(C36,"Sudah","Belum") -> Belum
A37: 36 | B37: peanut✰ | C37: =FALSE() -> FALSE | D37: =IF(C37,"Sudah","Belum") -> Belum
A38: 37 | B38: officeboy12 | C38: =FALSE() -> FALSE | D38: =IF(C38,"Sudah","Belum") -> Belum
A39: 38 | B39: hantu yang terlupakan | C39: =FALSE() -> FALSE | D39: =IF(C39,"Sudah","Belum") -> Belum
A40: 39 | B40: فارز | C40: =FALSE() -> FALSE | D40: =IF(C40,"Sudah","Belum") -> Belum
A41: 40 | B41: 2012🌺 | C41: =FALSE() -> FALSE | D41: =IF(C41,"Sudah","Belum") -> Belum
... A55: 54 | B55: jopipi | C55: =FALSE() -> FALSE | D55: =IF(C55,"Sudah","Belum") -> Belum
